[2025-10-28T14:11:29.876-0400] {local_task_job_runner.py:123} INFO - ::group::Pre task execution logs
[2025-10-28T14:11:29.879-0400] {taskinstance.py:2612} INFO - Dependencies all met for dep_context=non-requeueable deps ti=<TaskInstance: onboarding_data_pipeline.validation_tasks.detect_anomalies manual__2025-10-28T18:11:10.424320+00:00 [queued]>
[2025-10-28T14:11:29.881-0400] {taskinstance.py:2612} INFO - Dependencies all met for dep_context=requeueable deps ti=<TaskInstance: onboarding_data_pipeline.validation_tasks.detect_anomalies manual__2025-10-28T18:11:10.424320+00:00 [queued]>
[2025-10-28T14:11:29.881-0400] {taskinstance.py:2865} INFO - Starting attempt 1 of 3
[2025-10-28T14:11:29.884-0400] {taskinstance.py:2888} INFO - Executing <Task(PythonOperator): validation_tasks.detect_anomalies> on 2025-10-28 18:11:10.424320+00:00
[2025-10-28T14:11:29.889-0400] {standard_task_runner.py:72} INFO - Started process 91788 to run task
[2025-10-28T14:11:29.892-0400] {standard_task_runner.py:104} INFO - Running: ['airflow', 'tasks', 'run', 'onboarding_data_pipeline', 'validation_tasks.detect_anomalies', 'manual__2025-10-28T18:11:10.424320+00:00', '--job-id', '34', '--raw', '--subdir', 'DAGS_FOLDER/main_pipeline_dag.py', '--cfg-path', '/var/folders/bq/zp7dztbn5yxb9ljzbt_99_dr0000gn/T/tmpuq4p0hx_']
[2025-10-28T14:11:29.893-0400] {standard_task_runner.py:105} INFO - Job 34: Subtask validation_tasks.detect_anomalies
[2025-10-28T14:11:29.908-0400] {task_command.py:467} INFO - Running <TaskInstance: onboarding_data_pipeline.validation_tasks.detect_anomalies manual__2025-10-28T18:11:10.424320+00:00 [running]> on host mithuns-macbook-pro.local
[2025-10-28T14:11:29.925-0400] {taskinstance.py:3131} INFO - Exporting env vars: AIRFLOW_CTX_DAG_EMAIL='team13@example.com' AIRFLOW_CTX_DAG_OWNER='Team13' AIRFLOW_CTX_DAG_ID='onboarding_data_pipeline' AIRFLOW_CTX_TASK_ID='validation_tasks.detect_anomalies' AIRFLOW_CTX_EXECUTION_DATE='2025-10-28T18:11:10.424320+00:00' AIRFLOW_CTX_TRY_NUMBER='1' AIRFLOW_CTX_DAG_RUN_ID='manual__2025-10-28T18:11:10.424320+00:00'
[2025-10-28T14:11:29.926-0400] {logging_mixin.py:190} INFO - Task instance is in running state
[2025-10-28T14:11:29.926-0400] {logging_mixin.py:190} INFO -  Previous state of the Task instance: queued
[2025-10-28T14:11:29.926-0400] {logging_mixin.py:190} INFO - Current task name:validation_tasks.detect_anomalies state:running start_date:2025-10-28 18:11:29.879685+00:00
[2025-10-28T14:11:29.927-0400] {logging_mixin.py:190} INFO - Dag name:onboarding_data_pipeline and current dag run status:running
[2025-10-28T14:11:29.927-0400] {taskinstance.py:731} INFO - ::endgroup::
[2025-10-28T14:11:29.928-0400] {logging_mixin.py:190} INFO - Detecting data anomalies...
[2025-10-28T14:11:29.928-0400] {taskinstance.py:3310} ERROR - Task failed with exception
Traceback (most recent call last):
  File "/Library/Frameworks/Python.framework/Versions/3.11/lib/python3.11/site-packages/airflow/models/taskinstance.py", line 762, in _execute_task
    result = _execute_callable(context=context, **execute_callable_kwargs)
             ^^^^^^^^^^^^^^^^^^^^^^^^^^^^^^^^^^^^^^^^^^^^^^^^^^^^^^^^^^^^^
  File "/Library/Frameworks/Python.framework/Versions/3.11/lib/python3.11/site-packages/airflow/models/taskinstance.py", line 733, in _execute_callable
    return ExecutionCallableRunner(
           ^^^^^^^^^^^^^^^^^^^^^^^^
  File "/Library/Frameworks/Python.framework/Versions/3.11/lib/python3.11/site-packages/airflow/utils/operator_helpers.py", line 252, in run
    return self.func(*args, **kwargs)
           ^^^^^^^^^^^^^^^^^^^^^^^^^^
  File "/Library/Frameworks/Python.framework/Versions/3.11/lib/python3.11/site-packages/airflow/models/baseoperator.py", line 406, in wrapper
    return func(self, *args, **kwargs)
           ^^^^^^^^^^^^^^^^^^^^^^^^^^^
  File "/Library/Frameworks/Python.framework/Versions/3.11/lib/python3.11/site-packages/airflow/operators/python.py", line 238, in execute
    return_value = self.execute_callable()
                   ^^^^^^^^^^^^^^^^^^^^^^^
  File "/Library/Frameworks/Python.framework/Versions/3.11/lib/python3.11/site-packages/airflow/operators/python.py", line 256, in execute_callable
    return runner.run(*self.op_args, **self.op_kwargs)
           ^^^^^^^^^^^^^^^^^^^^^^^^^^^^^^^^^^^^^^^^^^^
  File "/Library/Frameworks/Python.framework/Versions/3.11/lib/python3.11/site-packages/airflow/utils/operator_helpers.py", line 252, in run
    return self.func(*args, **kwargs)
           ^^^^^^^^^^^^^^^^^^^^^^^^^^
  File "/Users/mithundineshkumar/Documents/Development/MLOps/Project/MLOPS-Test1/data-pipeline/airflow/dags/main_pipeline_dag.py", line 157, in detect_anomalies
    with open(report_path, 'w') as f:
         ^^^^^^^^^^^^^^^^^^^^^^
FileNotFoundError: [Errno 2] No such file or directory: '/Users/mithundineshkumar/Documents/Development/MLOps/Project/MLOPS-Test1/data/anomaly_report.json'
[2025-10-28T14:11:29.932-0400] {logging_mixin.py:190} INFO - Task instance in failure state
[2025-10-28T14:11:29.932-0400] {logging_mixin.py:190} INFO - Task start:2025-10-28 18:11:29.879685+00:00 end:2025-10-28 18:11:29.932404+00:00 duration:0.052719
[2025-10-28T14:11:29.932-0400] {logging_mixin.py:190} INFO - Task:<Task(PythonOperator): validation_tasks.detect_anomalies> dag:<DAG: onboarding_data_pipeline> dagrun:<DagRun onboarding_data_pipeline @ 2025-10-28 18:11:10.424320+00:00: manual__2025-10-28T18:11:10.424320+00:00, state:running, queued_at: 2025-10-28 18:11:10.447926+00:00. externally triggered: True>
[2025-10-28T14:11:29.933-0400] {logging_mixin.py:190} INFO - Failure caused by [Errno 2] No such file or directory: '/Users/mithundineshkumar/Documents/Development/MLOps/Project/MLOPS-Test1/data/anomaly_report.json'
[2025-10-28T14:11:29.933-0400] {taskinstance.py:1225} INFO - Marking task as UP_FOR_RETRY. dag_id=onboarding_data_pipeline, task_id=validation_tasks.detect_anomalies, run_id=manual__2025-10-28T18:11:10.424320+00:00, execution_date=20251028T181110, start_date=20251028T181129, end_date=20251028T181129
[2025-10-28T14:11:29.937-0400] {taskinstance.py:340} INFO - ::group::Post task execution logs
[2025-10-28T14:11:29.937-0400] {standard_task_runner.py:124} ERROR - Failed to execute job 34 for task validation_tasks.detect_anomalies ([Errno 2] No such file or directory: '/Users/mithundineshkumar/Documents/Development/MLOps/Project/MLOPS-Test1/data/anomaly_report.json'; 91788)
Traceback (most recent call last):
  File "/Library/Frameworks/Python.framework/Versions/3.11/lib/python3.11/site-packages/airflow/task/task_runner/standard_task_runner.py", line 117, in _start_by_fork
    ret = args.func(args, dag=self.dag)
          ^^^^^^^^^^^^^^^^^^^^^^^^^^^^^
  File "/Library/Frameworks/Python.framework/Versions/3.11/lib/python3.11/site-packages/airflow/cli/cli_config.py", line 49, in command
    return func(*args, **kwargs)
           ^^^^^^^^^^^^^^^^^^^^^
  File "/Library/Frameworks/Python.framework/Versions/3.11/lib/python3.11/site-packages/airflow/utils/cli.py", line 115, in wrapper
    return f(*args, **kwargs)
           ^^^^^^^^^^^^^^^^^^
  File "/Library/Frameworks/Python.framework/Versions/3.11/lib/python3.11/site-packages/airflow/cli/commands/task_command.py", line 483, in task_run
    task_return_code = _run_task_by_selected_method(args, _dag, ti)
                       ^^^^^^^^^^^^^^^^^^^^^^^^^^^^^^^^^^^^^^^^^^^^
  File "/Library/Frameworks/Python.framework/Versions/3.11/lib/python3.11/site-packages/airflow/cli/commands/task_command.py", line 256, in _run_task_by_selected_method
    return _run_raw_task(args, ti)
           ^^^^^^^^^^^^^^^^^^^^^^^
  File "/Library/Frameworks/Python.framework/Versions/3.11/lib/python3.11/site-packages/airflow/cli/commands/task_command.py", line 341, in _run_raw_task
    return ti._run_raw_task(
           ^^^^^^^^^^^^^^^^^
  File "/Library/Frameworks/Python.framework/Versions/3.11/lib/python3.11/site-packages/airflow/utils/session.py", line 97, in wrapper
    return func(*args, session=session, **kwargs)
           ^^^^^^^^^^^^^^^^^^^^^^^^^^^^^^^^^^^^^^
  File "/Library/Frameworks/Python.framework/Versions/3.11/lib/python3.11/site-packages/airflow/models/taskinstance.py", line 3004, in _run_raw_task
    return _run_raw_task(
           ^^^^^^^^^^^^^^
  File "/Library/Frameworks/Python.framework/Versions/3.11/lib/python3.11/site-packages/airflow/models/taskinstance.py", line 273, in _run_raw_task
    TaskInstance._execute_task_with_callbacks(
  File "/Library/Frameworks/Python.framework/Versions/3.11/lib/python3.11/site-packages/airflow/models/taskinstance.py", line 3158, in _execute_task_with_callbacks
    result = self._execute_task(context, task_orig)
             ^^^^^^^^^^^^^^^^^^^^^^^^^^^^^^^^^^^^^^
  File "/Library/Frameworks/Python.framework/Versions/3.11/lib/python3.11/site-packages/airflow/models/taskinstance.py", line 3182, in _execute_task
    return _execute_task(self, context, task_orig)
           ^^^^^^^^^^^^^^^^^^^^^^^^^^^^^^^^^^^^^^^
  File "/Library/Frameworks/Python.framework/Versions/3.11/lib/python3.11/site-packages/airflow/models/taskinstance.py", line 762, in _execute_task
    result = _execute_callable(context=context, **execute_callable_kwargs)
             ^^^^^^^^^^^^^^^^^^^^^^^^^^^^^^^^^^^^^^^^^^^^^^^^^^^^^^^^^^^^^
  File "/Library/Frameworks/Python.framework/Versions/3.11/lib/python3.11/site-packages/airflow/models/taskinstance.py", line 733, in _execute_callable
    return ExecutionCallableRunner(
           ^^^^^^^^^^^^^^^^^^^^^^^^
  File "/Library/Frameworks/Python.framework/Versions/3.11/lib/python3.11/site-packages/airflow/utils/operator_helpers.py", line 252, in run
    return self.func(*args, **kwargs)
           ^^^^^^^^^^^^^^^^^^^^^^^^^^
  File "/Library/Frameworks/Python.framework/Versions/3.11/lib/python3.11/site-packages/airflow/models/baseoperator.py", line 406, in wrapper
    return func(self, *args, **kwargs)
           ^^^^^^^^^^^^^^^^^^^^^^^^^^^
  File "/Library/Frameworks/Python.framework/Versions/3.11/lib/python3.11/site-packages/airflow/operators/python.py", line 238, in execute
    return_value = self.execute_callable()
                   ^^^^^^^^^^^^^^^^^^^^^^^
  File "/Library/Frameworks/Python.framework/Versions/3.11/lib/python3.11/site-packages/airflow/operators/python.py", line 256, in execute_callable
    return runner.run(*self.op_args, **self.op_kwargs)
           ^^^^^^^^^^^^^^^^^^^^^^^^^^^^^^^^^^^^^^^^^^^
  File "/Library/Frameworks/Python.framework/Versions/3.11/lib/python3.11/site-packages/airflow/utils/operator_helpers.py", line 252, in run
    return self.func(*args, **kwargs)
           ^^^^^^^^^^^^^^^^^^^^^^^^^^
  File "/Users/mithundineshkumar/Documents/Development/MLOps/Project/MLOPS-Test1/data-pipeline/airflow/dags/main_pipeline_dag.py", line 157, in detect_anomalies
    with open(report_path, 'w') as f:
         ^^^^^^^^^^^^^^^^^^^^^^
FileNotFoundError: [Errno 2] No such file or directory: '/Users/mithundineshkumar/Documents/Development/MLOps/Project/MLOPS-Test1/data/anomaly_report.json'
[2025-10-28T14:11:29.945-0400] {local_task_job_runner.py:266} INFO - Task exited with return code 1
[2025-10-28T14:11:29.951-0400] {taskinstance.py:3900} INFO - 0 downstream tasks scheduled from follow-on schedule check
[2025-10-28T14:11:29.951-0400] {local_task_job_runner.py:245} INFO - ::endgroup::
