[2025-10-28T15:34:35.846-0400] {local_task_job_runner.py:123} INFO - ::group::Pre task execution logs
[2025-10-28T15:34:35.848-0400] {taskinstance.py:2612} INFO - Dependencies all met for dep_context=non-requeueable deps ti=<TaskInstance: onboarding_data_pipeline.preprocessing_tasks.clean_text manual__2025-10-28T19:08:25.527216+00:00 [queued]>
[2025-10-28T15:34:35.850-0400] {taskinstance.py:2612} INFO - Dependencies all met for dep_context=requeueable deps ti=<TaskInstance: onboarding_data_pipeline.preprocessing_tasks.clean_text manual__2025-10-28T19:08:25.527216+00:00 [queued]>
[2025-10-28T15:34:35.850-0400] {taskinstance.py:2865} INFO - Starting attempt 3 of 3
[2025-10-28T15:34:35.853-0400] {taskinstance.py:2888} INFO - Executing <Task(PythonOperator): preprocessing_tasks.clean_text> on 2025-10-28 19:08:25.527216+00:00
[2025-10-28T15:34:35.856-0400] {standard_task_runner.py:72} INFO - Started process 21485 to run task
[2025-10-28T15:34:35.859-0400] {standard_task_runner.py:104} INFO - Running: ['airflow', 'tasks', 'run', 'onboarding_data_pipeline', 'preprocessing_tasks.clean_text', 'manual__2025-10-28T19:08:25.527216+00:00', '--job-id', '89', '--raw', '--subdir', 'DAGS_FOLDER/main_pipeline_dag.py', '--cfg-path', '/var/folders/bq/zp7dztbn5yxb9ljzbt_99_dr0000gn/T/tmpqqepreew']
[2025-10-28T15:34:35.860-0400] {standard_task_runner.py:105} INFO - Job 89: Subtask preprocessing_tasks.clean_text
[2025-10-28T15:34:35.876-0400] {task_command.py:467} INFO - Running <TaskInstance: onboarding_data_pipeline.preprocessing_tasks.clean_text manual__2025-10-28T19:08:25.527216+00:00 [running]> on host mithuns-macbook-pro.local
[2025-10-28T15:34:35.892-0400] {taskinstance.py:3131} INFO - Exporting env vars: AIRFLOW_CTX_DAG_EMAIL='mithun.feb2024@gmail.com' AIRFLOW_CTX_DAG_OWNER='Team13' AIRFLOW_CTX_DAG_ID='onboarding_data_pipeline' AIRFLOW_CTX_TASK_ID='preprocessing_tasks.clean_text' AIRFLOW_CTX_EXECUTION_DATE='2025-10-28T19:08:25.527216+00:00' AIRFLOW_CTX_TRY_NUMBER='3' AIRFLOW_CTX_DAG_RUN_ID='manual__2025-10-28T19:08:25.527216+00:00'
[2025-10-28T15:34:35.893-0400] {logging_mixin.py:190} INFO - Task instance is in running state
[2025-10-28T15:34:35.893-0400] {logging_mixin.py:190} INFO -  Previous state of the Task instance: queued
[2025-10-28T15:34:35.893-0400] {logging_mixin.py:190} INFO - Current task name:preprocessing_tasks.clean_text state:running start_date:2025-10-28 19:34:35.849060+00:00
[2025-10-28T15:34:35.893-0400] {logging_mixin.py:190} INFO - Dag name:onboarding_data_pipeline and current dag run status:running
[2025-10-28T15:34:35.893-0400] {taskinstance.py:731} INFO - ::endgroup::
[2025-10-28T15:34:35.894-0400] {logging_mixin.py:190} INFO - Simulating text cleaning...
[2025-10-28T15:34:35.896-0400] {taskinstance.py:3310} ERROR - Task failed with exception
Traceback (most recent call last):
  File "/Library/Frameworks/Python.framework/Versions/3.11/lib/python3.11/site-packages/airflow/models/taskinstance.py", line 762, in _execute_task
    result = _execute_callable(context=context, **execute_callable_kwargs)
             ^^^^^^^^^^^^^^^^^^^^^^^^^^^^^^^^^^^^^^^^^^^^^^^^^^^^^^^^^^^^^
  File "/Library/Frameworks/Python.framework/Versions/3.11/lib/python3.11/site-packages/airflow/models/taskinstance.py", line 733, in _execute_callable
    return ExecutionCallableRunner(
           ^^^^^^^^^^^^^^^^^^^^^^^^
  File "/Library/Frameworks/Python.framework/Versions/3.11/lib/python3.11/site-packages/airflow/utils/operator_helpers.py", line 252, in run
    return self.func(*args, **kwargs)
           ^^^^^^^^^^^^^^^^^^^^^^^^^^
  File "/Library/Frameworks/Python.framework/Versions/3.11/lib/python3.11/site-packages/airflow/models/baseoperator.py", line 406, in wrapper
    return func(self, *args, **kwargs)
           ^^^^^^^^^^^^^^^^^^^^^^^^^^^
  File "/Library/Frameworks/Python.framework/Versions/3.11/lib/python3.11/site-packages/airflow/operators/python.py", line 238, in execute
    return_value = self.execute_callable()
                   ^^^^^^^^^^^^^^^^^^^^^^^
  File "/Library/Frameworks/Python.framework/Versions/3.11/lib/python3.11/site-packages/airflow/operators/python.py", line 256, in execute_callable
    return runner.run(*self.op_args, **self.op_kwargs)
           ^^^^^^^^^^^^^^^^^^^^^^^^^^^^^^^^^^^^^^^^^^^
  File "/Library/Frameworks/Python.framework/Versions/3.11/lib/python3.11/site-packages/airflow/utils/operator_helpers.py", line 252, in run
    return self.func(*args, **kwargs)
           ^^^^^^^^^^^^^^^^^^^^^^^^^^
  File "/Users/mithundineshkumar/Documents/Development/MLOps/Project/MLOPS-Test1/data-pipeline/airflow/dags/main_pipeline_dag.py", line 28, in clean_all_text
    raise Exception("Test failure: This is a simulated task failure to test Airflow email alerts.")
Exception: Test failure: This is a simulated task failure to test Airflow email alerts.
[2025-10-28T15:34:35.899-0400] {logging_mixin.py:190} INFO - Task instance in failure state
[2025-10-28T15:34:35.899-0400] {logging_mixin.py:190} INFO - Task start:2025-10-28 19:34:35.849060+00:00 end:2025-10-28 19:34:35.898911+00:00 duration:0.049851
[2025-10-28T15:34:35.899-0400] {logging_mixin.py:190} INFO - Task:<Task(PythonOperator): preprocessing_tasks.clean_text> dag:<DAG: onboarding_data_pipeline> dagrun:<DagRun onboarding_data_pipeline @ 2025-10-28 19:08:25.527216+00:00: manual__2025-10-28T19:08:25.527216+00:00, state:running, queued_at: 2025-10-28 19:08:25.532553+00:00. externally triggered: True>
[2025-10-28T15:34:35.899-0400] {logging_mixin.py:190} INFO - Failure caused by Test failure: This is a simulated task failure to test Airflow email alerts.
[2025-10-28T15:34:35.900-0400] {taskinstance.py:1225} INFO - Marking task as FAILED. dag_id=onboarding_data_pipeline, task_id=preprocessing_tasks.clean_text, run_id=manual__2025-10-28T19:08:25.527216+00:00, execution_date=20251028T190825, start_date=20251028T193435, end_date=20251028T193435
[2025-10-28T15:34:35.905-0400] {base.py:84} INFO - Retrieving connection 'smtp_default'
[2025-10-28T15:34:35.905-0400] {email.py:272} INFO - Email alerting: attempt 1
[2025-10-28T15:34:36.798-0400] {base.py:84} INFO - Retrieving connection 'smtp_default'
[2025-10-28T15:34:36.799-0400] {email.py:272} INFO - Email alerting: attempt 1
[2025-10-28T15:34:38.018-0400] {taskinstance.py:1234} ERROR - Failed to send email to: ['mithun.feb2024@gmail.com']
Traceback (most recent call last):
  File "/Library/Frameworks/Python.framework/Versions/3.11/lib/python3.11/site-packages/airflow/models/taskinstance.py", line 273, in _run_raw_task
    TaskInstance._execute_task_with_callbacks(
  File "/Library/Frameworks/Python.framework/Versions/3.11/lib/python3.11/site-packages/airflow/models/taskinstance.py", line 3158, in _execute_task_with_callbacks
    result = self._execute_task(context, task_orig)
             ^^^^^^^^^^^^^^^^^^^^^^^^^^^^^^^^^^^^^^
  File "/Library/Frameworks/Python.framework/Versions/3.11/lib/python3.11/site-packages/airflow/models/taskinstance.py", line 3182, in _execute_task
    return _execute_task(self, context, task_orig)
           ^^^^^^^^^^^^^^^^^^^^^^^^^^^^^^^^^^^^^^^
  File "/Library/Frameworks/Python.framework/Versions/3.11/lib/python3.11/site-packages/airflow/models/taskinstance.py", line 762, in _execute_task
    result = _execute_callable(context=context, **execute_callable_kwargs)
             ^^^^^^^^^^^^^^^^^^^^^^^^^^^^^^^^^^^^^^^^^^^^^^^^^^^^^^^^^^^^^
  File "/Library/Frameworks/Python.framework/Versions/3.11/lib/python3.11/site-packages/airflow/models/taskinstance.py", line 733, in _execute_callable
    return ExecutionCallableRunner(
           ^^^^^^^^^^^^^^^^^^^^^^^^
  File "/Library/Frameworks/Python.framework/Versions/3.11/lib/python3.11/site-packages/airflow/utils/operator_helpers.py", line 252, in run
    return self.func(*args, **kwargs)
           ^^^^^^^^^^^^^^^^^^^^^^^^^^
  File "/Library/Frameworks/Python.framework/Versions/3.11/lib/python3.11/site-packages/airflow/models/baseoperator.py", line 406, in wrapper
    return func(self, *args, **kwargs)
           ^^^^^^^^^^^^^^^^^^^^^^^^^^^
  File "/Library/Frameworks/Python.framework/Versions/3.11/lib/python3.11/site-packages/airflow/operators/python.py", line 238, in execute
    return_value = self.execute_callable()
                   ^^^^^^^^^^^^^^^^^^^^^^^
  File "/Library/Frameworks/Python.framework/Versions/3.11/lib/python3.11/site-packages/airflow/operators/python.py", line 256, in execute_callable
    return runner.run(*self.op_args, **self.op_kwargs)
           ^^^^^^^^^^^^^^^^^^^^^^^^^^^^^^^^^^^^^^^^^^^
  File "/Library/Frameworks/Python.framework/Versions/3.11/lib/python3.11/site-packages/airflow/utils/operator_helpers.py", line 252, in run
    return self.func(*args, **kwargs)
           ^^^^^^^^^^^^^^^^^^^^^^^^^^
  File "/Users/mithundineshkumar/Documents/Development/MLOps/Project/MLOPS-Test1/data-pipeline/airflow/dags/main_pipeline_dag.py", line 28, in clean_all_text
    raise Exception("Test failure: This is a simulated task failure to test Airflow email alerts.")
Exception: Test failure: This is a simulated task failure to test Airflow email alerts.

During handling of the above exception, another exception occurred:

Traceback (most recent call last):
  File "/Library/Frameworks/Python.framework/Versions/3.11/lib/python3.11/site-packages/airflow/models/taskinstance.py", line 1442, in _email_alert
    send_email(task.email, subject, html_content)
  File "/Library/Frameworks/Python.framework/Versions/3.11/lib/python3.11/site-packages/airflow/utils/email.py", line 80, in send_email
    return backend(
           ^^^^^^^^
  File "/Library/Frameworks/Python.framework/Versions/3.11/lib/python3.11/site-packages/airflow/utils/email.py", line 155, in send_email_smtp
    send_mime_email(e_from=mail_from, e_to=recipients, mime_msg=msg, conn_id=conn_id, dryrun=dryrun)
  File "/Library/Frameworks/Python.framework/Versions/3.11/lib/python3.11/site-packages/airflow/utils/email.py", line 282, in send_mime_email
    smtp_conn.login(smtp_user, smtp_password)
  File "/Library/Frameworks/Python.framework/Versions/3.11/lib/python3.11/smtplib.py", line 750, in login
    raise last_exception
  File "/Library/Frameworks/Python.framework/Versions/3.11/lib/python3.11/smtplib.py", line 739, in login
    (code, resp) = self.auth(
                   ^^^^^^^^^^
  File "/Library/Frameworks/Python.framework/Versions/3.11/lib/python3.11/smtplib.py", line 662, in auth
    raise SMTPAuthenticationError(code, resp)
smtplib.SMTPAuthenticationError: (535, b'5.7.8 Username and Password not accepted. For more information, go to\n5.7.8  https://support.google.com/mail/?p=BadCredentials d75a77b69052e-4eba387a61bsm77250451cf.36 - gsmtp')

During handling of the above exception, another exception occurred:

Traceback (most recent call last):
  File "/Library/Frameworks/Python.framework/Versions/3.11/lib/python3.11/site-packages/airflow/models/taskinstance.py", line 1232, in _handle_failure
    task_instance.email_alert(error, failure_context["task"])
  File "/Library/Frameworks/Python.framework/Versions/3.11/lib/python3.11/site-packages/airflow/models/taskinstance.py", line 3604, in email_alert
    _email_alert(task_instance=self, exception=exception, task=task)
  File "/Library/Frameworks/Python.framework/Versions/3.11/lib/python3.11/site-packages/airflow/models/taskinstance.py", line 1444, in _email_alert
    send_email(task.email, subject, html_content_err)
  File "/Library/Frameworks/Python.framework/Versions/3.11/lib/python3.11/site-packages/airflow/utils/email.py", line 80, in send_email
    return backend(
           ^^^^^^^^
  File "/Library/Frameworks/Python.framework/Versions/3.11/lib/python3.11/site-packages/airflow/utils/email.py", line 155, in send_email_smtp
    send_mime_email(e_from=mail_from, e_to=recipients, mime_msg=msg, conn_id=conn_id, dryrun=dryrun)
  File "/Library/Frameworks/Python.framework/Versions/3.11/lib/python3.11/site-packages/airflow/utils/email.py", line 282, in send_mime_email
    smtp_conn.login(smtp_user, smtp_password)
  File "/Library/Frameworks/Python.framework/Versions/3.11/lib/python3.11/smtplib.py", line 750, in login
    raise last_exception
  File "/Library/Frameworks/Python.framework/Versions/3.11/lib/python3.11/smtplib.py", line 739, in login
    (code, resp) = self.auth(
                   ^^^^^^^^^^
  File "/Library/Frameworks/Python.framework/Versions/3.11/lib/python3.11/smtplib.py", line 662, in auth
    raise SMTPAuthenticationError(code, resp)
smtplib.SMTPAuthenticationError: (535, b'5.7.8 Username and Password not accepted. For more information, go to\n5.7.8  https://support.google.com/mail/?p=BadCredentials af79cd13be357-89f24cd5938sm871898685a.20 - gsmtp')
[2025-10-28T15:34:38.027-0400] {taskinstance.py:340} INFO - ::group::Post task execution logs
[2025-10-28T15:34:38.028-0400] {standard_task_runner.py:124} ERROR - Failed to execute job 89 for task preprocessing_tasks.clean_text (Test failure: This is a simulated task failure to test Airflow email alerts.; 21485)
Traceback (most recent call last):
  File "/Library/Frameworks/Python.framework/Versions/3.11/lib/python3.11/site-packages/airflow/task/task_runner/standard_task_runner.py", line 117, in _start_by_fork
    ret = args.func(args, dag=self.dag)
          ^^^^^^^^^^^^^^^^^^^^^^^^^^^^^
  File "/Library/Frameworks/Python.framework/Versions/3.11/lib/python3.11/site-packages/airflow/cli/cli_config.py", line 49, in command
    return func(*args, **kwargs)
           ^^^^^^^^^^^^^^^^^^^^^
  File "/Library/Frameworks/Python.framework/Versions/3.11/lib/python3.11/site-packages/airflow/utils/cli.py", line 115, in wrapper
    return f(*args, **kwargs)
           ^^^^^^^^^^^^^^^^^^
  File "/Library/Frameworks/Python.framework/Versions/3.11/lib/python3.11/site-packages/airflow/cli/commands/task_command.py", line 483, in task_run
    task_return_code = _run_task_by_selected_method(args, _dag, ti)
                       ^^^^^^^^^^^^^^^^^^^^^^^^^^^^^^^^^^^^^^^^^^^^
  File "/Library/Frameworks/Python.framework/Versions/3.11/lib/python3.11/site-packages/airflow/cli/commands/task_command.py", line 256, in _run_task_by_selected_method
    return _run_raw_task(args, ti)
           ^^^^^^^^^^^^^^^^^^^^^^^
  File "/Library/Frameworks/Python.framework/Versions/3.11/lib/python3.11/site-packages/airflow/cli/commands/task_command.py", line 341, in _run_raw_task
    return ti._run_raw_task(
           ^^^^^^^^^^^^^^^^^
  File "/Library/Frameworks/Python.framework/Versions/3.11/lib/python3.11/site-packages/airflow/utils/session.py", line 97, in wrapper
    return func(*args, session=session, **kwargs)
           ^^^^^^^^^^^^^^^^^^^^^^^^^^^^^^^^^^^^^^
  File "/Library/Frameworks/Python.framework/Versions/3.11/lib/python3.11/site-packages/airflow/models/taskinstance.py", line 3004, in _run_raw_task
    return _run_raw_task(
           ^^^^^^^^^^^^^^
  File "/Library/Frameworks/Python.framework/Versions/3.11/lib/python3.11/site-packages/airflow/models/taskinstance.py", line 273, in _run_raw_task
    TaskInstance._execute_task_with_callbacks(
  File "/Library/Frameworks/Python.framework/Versions/3.11/lib/python3.11/site-packages/airflow/models/taskinstance.py", line 3158, in _execute_task_with_callbacks
    result = self._execute_task(context, task_orig)
             ^^^^^^^^^^^^^^^^^^^^^^^^^^^^^^^^^^^^^^
  File "/Library/Frameworks/Python.framework/Versions/3.11/lib/python3.11/site-packages/airflow/models/taskinstance.py", line 3182, in _execute_task
    return _execute_task(self, context, task_orig)
           ^^^^^^^^^^^^^^^^^^^^^^^^^^^^^^^^^^^^^^^
  File "/Library/Frameworks/Python.framework/Versions/3.11/lib/python3.11/site-packages/airflow/models/taskinstance.py", line 762, in _execute_task
    result = _execute_callable(context=context, **execute_callable_kwargs)
             ^^^^^^^^^^^^^^^^^^^^^^^^^^^^^^^^^^^^^^^^^^^^^^^^^^^^^^^^^^^^^
  File "/Library/Frameworks/Python.framework/Versions/3.11/lib/python3.11/site-packages/airflow/models/taskinstance.py", line 733, in _execute_callable
    return ExecutionCallableRunner(
           ^^^^^^^^^^^^^^^^^^^^^^^^
  File "/Library/Frameworks/Python.framework/Versions/3.11/lib/python3.11/site-packages/airflow/utils/operator_helpers.py", line 252, in run
    return self.func(*args, **kwargs)
           ^^^^^^^^^^^^^^^^^^^^^^^^^^
  File "/Library/Frameworks/Python.framework/Versions/3.11/lib/python3.11/site-packages/airflow/models/baseoperator.py", line 406, in wrapper
    return func(self, *args, **kwargs)
           ^^^^^^^^^^^^^^^^^^^^^^^^^^^
  File "/Library/Frameworks/Python.framework/Versions/3.11/lib/python3.11/site-packages/airflow/operators/python.py", line 238, in execute
    return_value = self.execute_callable()
                   ^^^^^^^^^^^^^^^^^^^^^^^
  File "/Library/Frameworks/Python.framework/Versions/3.11/lib/python3.11/site-packages/airflow/operators/python.py", line 256, in execute_callable
    return runner.run(*self.op_args, **self.op_kwargs)
           ^^^^^^^^^^^^^^^^^^^^^^^^^^^^^^^^^^^^^^^^^^^
  File "/Library/Frameworks/Python.framework/Versions/3.11/lib/python3.11/site-packages/airflow/utils/operator_helpers.py", line 252, in run
    return self.func(*args, **kwargs)
           ^^^^^^^^^^^^^^^^^^^^^^^^^^
  File "/Users/mithundineshkumar/Documents/Development/MLOps/Project/MLOPS-Test1/data-pipeline/airflow/dags/main_pipeline_dag.py", line 28, in clean_all_text
    raise Exception("Test failure: This is a simulated task failure to test Airflow email alerts.")
Exception: Test failure: This is a simulated task failure to test Airflow email alerts.
[2025-10-28T15:34:38.044-0400] {local_task_job_runner.py:266} INFO - Task exited with return code 1
[2025-10-28T15:34:38.055-0400] {taskinstance.py:3900} INFO - 0 downstream tasks scheduled from follow-on schedule check
[2025-10-28T15:34:38.057-0400] {local_task_job_runner.py:245} INFO - ::endgroup::
