[2025-10-27T17:02:22.302-0400] {taskinstance.py:1157} INFO - Dependencies all met for dep_context=non-requeueable deps ti=<TaskInstance: onboarding_data_pipeline.check_environment manual__2025-10-27T21:02:18.591873+00:00 [queued]>
[2025-10-27T17:02:22.304-0400] {taskinstance.py:1157} INFO - Dependencies all met for dep_context=requeueable deps ti=<TaskInstance: onboarding_data_pipeline.check_environment manual__2025-10-27T21:02:18.591873+00:00 [queued]>
[2025-10-27T17:02:22.304-0400] {taskinstance.py:1359} INFO - Starting attempt 1 of 3
[2025-10-27T17:02:22.308-0400] {taskinstance.py:1380} INFO - Executing <Task(PythonOperator): check_environment> on 2025-10-27 21:02:18.591873+00:00
[2025-10-27T17:02:22.311-0400] {standard_task_runner.py:57} INFO - Started process 55361 to run task
[2025-10-27T17:02:22.314-0400] {standard_task_runner.py:84} INFO - Running: ['airflow', 'tasks', 'run', 'onboarding_data_pipeline', 'check_environment', 'manual__2025-10-27T21:02:18.591873+00:00', '--job-id', '2', '--raw', '--subdir', 'DAGS_FOLDER/main_pipeline_dag.py', '--cfg-path', '/var/folders/bq/zp7dztbn5yxb9ljzbt_99_dr0000gn/T/tmprz0ixdkf']
[2025-10-27T17:02:22.315-0400] {standard_task_runner.py:85} INFO - Job 2: Subtask check_environment
[2025-10-27T17:02:22.332-0400] {task_command.py:415} INFO - Running <TaskInstance: onboarding_data_pipeline.check_environment manual__2025-10-27T21:02:18.591873+00:00 [running]> on host mithuns-macbook-pro.local
[2025-10-27T17:02:22.347-0400] {taskinstance.py:1660} INFO - Exporting env vars: AIRFLOW_CTX_DAG_EMAIL='team13@example.com' AIRFLOW_CTX_DAG_OWNER='Team13' AIRFLOW_CTX_DAG_ID='onboarding_data_pipeline' AIRFLOW_CTX_TASK_ID='check_environment' AIRFLOW_CTX_EXECUTION_DATE='2025-10-27T21:02:18.591873+00:00' AIRFLOW_CTX_TRY_NUMBER='1' AIRFLOW_CTX_DAG_RUN_ID='manual__2025-10-27T21:02:18.591873+00:00'
[2025-10-27T17:02:22.348-0400] {logging_mixin.py:151} INFO - Checking environment setup...
[2025-10-27T17:02:22.348-0400] {taskinstance.py:1935} ERROR - Task failed with exception
Traceback (most recent call last):
  File "/opt/anaconda3/envs/oaenv/lib/python3.9/pathlib.py", line 1251, in mkdir
    self._accessor.mkdir(self, mode)
FileNotFoundError: [Errno 2] No such file or directory: '/opt/airflow/data/raw'

During handling of the above exception, another exception occurred:

Traceback (most recent call last):
  File "/opt/anaconda3/envs/oaenv/lib/python3.9/pathlib.py", line 1251, in mkdir
    self._accessor.mkdir(self, mode)
FileNotFoundError: [Errno 2] No such file or directory: '/opt/airflow/data'

During handling of the above exception, another exception occurred:

Traceback (most recent call last):
  File "/opt/anaconda3/envs/oaenv/lib/python3.9/site-packages/airflow/operators/python.py", line 192, in execute
    return_value = self.execute_callable()
  File "/opt/anaconda3/envs/oaenv/lib/python3.9/site-packages/airflow/operators/python.py", line 209, in execute_callable
    return self.python_callable(*self.op_args, **self.op_kwargs)
  File "/Users/mithundineshkumar/Documents/Development/MLOps/Project/MLOPS-Test1/data-pipeline/airflow/dags/main_pipeline_dag.py", line 110, in check_environment
    full_path.mkdir(parents=True, exist_ok=True)
  File "/opt/anaconda3/envs/oaenv/lib/python3.9/pathlib.py", line 1255, in mkdir
    self.parent.mkdir(parents=True, exist_ok=True)
  File "/opt/anaconda3/envs/oaenv/lib/python3.9/pathlib.py", line 1255, in mkdir
    self.parent.mkdir(parents=True, exist_ok=True)
  File "/opt/anaconda3/envs/oaenv/lib/python3.9/pathlib.py", line 1251, in mkdir
    self._accessor.mkdir(self, mode)
PermissionError: [Errno 13] Permission denied: '/opt/airflow'
[2025-10-27T17:02:22.351-0400] {taskinstance.py:1398} INFO - Marking task as UP_FOR_RETRY. dag_id=onboarding_data_pipeline, task_id=check_environment, execution_date=20251027T210218, start_date=20251027T210222, end_date=20251027T210222
[2025-10-27T17:02:22.353-0400] {standard_task_runner.py:104} ERROR - Failed to execute job 2 for task check_environment ([Errno 13] Permission denied: '/opt/airflow'; 55361)
[2025-10-27T17:02:22.368-0400] {local_task_job_runner.py:228} INFO - Task exited with return code 1
[2025-10-27T17:02:22.375-0400] {taskinstance.py:2776} INFO - 0 downstream tasks scheduled from follow-on schedule check
