[2025-10-27T17:13:29.223-0400] {taskinstance.py:1157} INFO - Dependencies all met for dep_context=non-requeueable deps ti=<TaskInstance: onboarding_data_pipeline.check_environment manual__2025-10-27T21:02:18.591873+00:00 [queued]>
[2025-10-27T17:13:29.225-0400] {taskinstance.py:1157} INFO - Dependencies all met for dep_context=requeueable deps ti=<TaskInstance: onboarding_data_pipeline.check_environment manual__2025-10-27T21:02:18.591873+00:00 [queued]>
[2025-10-27T17:13:29.225-0400] {taskinstance.py:1359} INFO - Starting attempt 3 of 3
[2025-10-27T17:13:29.229-0400] {taskinstance.py:1380} INFO - Executing <Task(PythonOperator): check_environment> on 2025-10-27 21:02:18.591873+00:00
[2025-10-27T17:13:29.233-0400] {standard_task_runner.py:57} INFO - Started process 61527 to run task
[2025-10-27T17:13:29.235-0400] {standard_task_runner.py:84} INFO - Running: ['airflow', 'tasks', 'run', 'onboarding_data_pipeline', 'check_environment', 'manual__2025-10-27T21:02:18.591873+00:00', '--job-id', '4', '--raw', '--subdir', 'DAGS_FOLDER/main_pipeline_dag.py', '--cfg-path', '/var/folders/bq/zp7dztbn5yxb9ljzbt_99_dr0000gn/T/tmpp89m05sh']
[2025-10-27T17:13:29.237-0400] {standard_task_runner.py:85} INFO - Job 4: Subtask check_environment
[2025-10-27T17:13:29.253-0400] {task_command.py:415} INFO - Running <TaskInstance: onboarding_data_pipeline.check_environment manual__2025-10-27T21:02:18.591873+00:00 [running]> on host mithuns-macbook-pro.local
[2025-10-27T17:13:29.268-0400] {taskinstance.py:1660} INFO - Exporting env vars: AIRFLOW_CTX_DAG_EMAIL='team13@example.com' AIRFLOW_CTX_DAG_OWNER='Team13' AIRFLOW_CTX_DAG_ID='onboarding_data_pipeline' AIRFLOW_CTX_TASK_ID='check_environment' AIRFLOW_CTX_EXECUTION_DATE='2025-10-27T21:02:18.591873+00:00' AIRFLOW_CTX_TRY_NUMBER='3' AIRFLOW_CTX_DAG_RUN_ID='manual__2025-10-27T21:02:18.591873+00:00'
[2025-10-27T17:13:29.269-0400] {logging_mixin.py:151} INFO - Checking environment setup...
[2025-10-27T17:13:29.269-0400] {logging_mixin.py:151} INFO - Created directory: /Users/mithundineshkumar/Documents/Development/MLOps/Project/MLOPS-Test1/data-pipeline/airflow/dags/data/raw
[2025-10-27T17:13:29.270-0400] {logging_mixin.py:151} INFO - Created directory: /Users/mithundineshkumar/Documents/Development/MLOps/Project/MLOPS-Test1/data-pipeline/airflow/dags/data/processed/cleaned
[2025-10-27T17:13:29.270-0400] {logging_mixin.py:151} INFO - Created directory: /Users/mithundineshkumar/Documents/Development/MLOps/Project/MLOPS-Test1/data-pipeline/airflow/dags/data/processed/chunked
[2025-10-27T17:13:29.270-0400] {logging_mixin.py:151} INFO - Created directory: /Users/mithundineshkumar/Documents/Development/MLOps/Project/MLOPS-Test1/data-pipeline/airflow/dags/data/curated
[2025-10-27T17:13:29.270-0400] {logging_mixin.py:151} INFO - Created directory: /Users/mithundineshkumar/Documents/Development/MLOps/Project/MLOPS-Test1/data-pipeline/airflow/dags/logs/pipeline
[2025-10-27T17:13:29.270-0400] {taskinstance.py:1935} ERROR - Task failed with exception
Traceback (most recent call last):
  File "/opt/anaconda3/envs/oaenv/lib/python3.9/site-packages/airflow/operators/python.py", line 192, in execute
    return_value = self.execute_callable()
  File "/opt/anaconda3/envs/oaenv/lib/python3.9/site-packages/airflow/operators/python.py", line 209, in execute_callable
    return self.python_callable(*self.op_args, **self.op_kwargs)
  File "/Users/mithundineshkumar/Documents/Development/MLOps/Project/MLOPS-Test1/data-pipeline/airflow/dags/main_pipeline_dag.py", line 125, in check_environment
    for json_file in json_files:
NameError: name 'json_files' is not defined
[2025-10-27T17:13:29.272-0400] {taskinstance.py:1398} INFO - Marking task as FAILED. dag_id=onboarding_data_pipeline, task_id=check_environment, execution_date=20251027T210218, start_date=20251027T211329, end_date=20251027T211329
[2025-10-27T17:13:29.276-0400] {logging_mixin.py:151} WARNING - /opt/anaconda3/envs/oaenv/lib/python3.9/site-packages/airflow/utils/email.py:154 RemovedInAirflow3Warning: Fetching SMTP credentials from configuration variables will be deprecated in a future release. Please set credentials using a connection instead.
[2025-10-27T17:13:29.277-0400] {configuration.py:1063} WARNING - section/key [smtp/smtp_user] not found in config
[2025-10-27T17:13:29.277-0400] {email.py:270} INFO - Email alerting: attempt 1
[2025-10-27T17:13:29.278-0400] {configuration.py:1063} WARNING - section/key [smtp/smtp_user] not found in config
[2025-10-27T17:13:29.279-0400] {email.py:270} INFO - Email alerting: attempt 1
[2025-10-27T17:13:29.279-0400] {taskinstance.py:2005} ERROR - Failed to send email to: ['team13@example.com']
Traceback (most recent call last):
  File "/opt/anaconda3/envs/oaenv/lib/python3.9/site-packages/airflow/models/taskinstance.py", line 1516, in _run_raw_task
    self._execute_task_with_callbacks(context, test_mode, session=session)
  File "/opt/anaconda3/envs/oaenv/lib/python3.9/site-packages/airflow/models/taskinstance.py", line 1679, in _execute_task_with_callbacks
    result = self._execute_task(context, task_orig)
  File "/opt/anaconda3/envs/oaenv/lib/python3.9/site-packages/airflow/models/taskinstance.py", line 1737, in _execute_task
    result = execute_callable(context=context, **execute_callable_kwargs)
  File "/opt/anaconda3/envs/oaenv/lib/python3.9/site-packages/airflow/operators/python.py", line 192, in execute
    return_value = self.execute_callable()
  File "/opt/anaconda3/envs/oaenv/lib/python3.9/site-packages/airflow/operators/python.py", line 209, in execute_callable
    return self.python_callable(*self.op_args, **self.op_kwargs)
  File "/Users/mithundineshkumar/Documents/Development/MLOps/Project/MLOPS-Test1/data-pipeline/airflow/dags/main_pipeline_dag.py", line 125, in check_environment
    for json_file in json_files:
NameError: name 'json_files' is not defined

During handling of the above exception, another exception occurred:

Traceback (most recent call last):
  File "/opt/anaconda3/envs/oaenv/lib/python3.9/site-packages/airflow/models/taskinstance.py", line 2418, in email_alert
    send_email(task.email, subject, html_content)
  File "/opt/anaconda3/envs/oaenv/lib/python3.9/site-packages/airflow/utils/email.py", line 80, in send_email
    return backend(
  File "/opt/anaconda3/envs/oaenv/lib/python3.9/site-packages/airflow/utils/email.py", line 154, in send_email_smtp
    send_mime_email(e_from=mail_from, e_to=recipients, mime_msg=msg, conn_id=conn_id, dryrun=dryrun)
  File "/opt/anaconda3/envs/oaenv/lib/python3.9/site-packages/airflow/utils/email.py", line 272, in send_mime_email
    smtp_conn = _get_smtp_connection(smtp_host, smtp_port, smtp_timeout, smtp_ssl)
  File "/opt/anaconda3/envs/oaenv/lib/python3.9/site-packages/airflow/utils/email.py", line 317, in _get_smtp_connection
    return smtplib.SMTP(host=host, port=port, timeout=timeout)
  File "/opt/anaconda3/envs/oaenv/lib/python3.9/smtplib.py", line 255, in __init__
    (code, msg) = self.connect(host, port)
  File "/opt/anaconda3/envs/oaenv/lib/python3.9/smtplib.py", line 341, in connect
    self.sock = self._get_socket(host, port, self.timeout)
  File "/opt/anaconda3/envs/oaenv/lib/python3.9/smtplib.py", line 312, in _get_socket
    return socket.create_connection((host, port), timeout,
  File "/opt/anaconda3/envs/oaenv/lib/python3.9/socket.py", line 856, in create_connection
    raise err
  File "/opt/anaconda3/envs/oaenv/lib/python3.9/socket.py", line 844, in create_connection
    sock.connect(sa)
ConnectionRefusedError: [Errno 61] Connection refused

During handling of the above exception, another exception occurred:

Traceback (most recent call last):
  File "/opt/anaconda3/envs/oaenv/lib/python3.9/site-packages/airflow/models/taskinstance.py", line 2003, in handle_failure
    self.email_alert(error, task)
  File "/opt/anaconda3/envs/oaenv/lib/python3.9/site-packages/airflow/models/taskinstance.py", line 2420, in email_alert
    send_email(task.email, subject, html_content_err)
  File "/opt/anaconda3/envs/oaenv/lib/python3.9/site-packages/airflow/utils/email.py", line 80, in send_email
    return backend(
  File "/opt/anaconda3/envs/oaenv/lib/python3.9/site-packages/airflow/utils/email.py", line 154, in send_email_smtp
    send_mime_email(e_from=mail_from, e_to=recipients, mime_msg=msg, conn_id=conn_id, dryrun=dryrun)
  File "/opt/anaconda3/envs/oaenv/lib/python3.9/site-packages/airflow/utils/email.py", line 272, in send_mime_email
    smtp_conn = _get_smtp_connection(smtp_host, smtp_port, smtp_timeout, smtp_ssl)
  File "/opt/anaconda3/envs/oaenv/lib/python3.9/site-packages/airflow/utils/email.py", line 317, in _get_smtp_connection
    return smtplib.SMTP(host=host, port=port, timeout=timeout)
  File "/opt/anaconda3/envs/oaenv/lib/python3.9/smtplib.py", line 255, in __init__
    (code, msg) = self.connect(host, port)
  File "/opt/anaconda3/envs/oaenv/lib/python3.9/smtplib.py", line 341, in connect
    self.sock = self._get_socket(host, port, self.timeout)
  File "/opt/anaconda3/envs/oaenv/lib/python3.9/smtplib.py", line 312, in _get_socket
    return socket.create_connection((host, port), timeout,
  File "/opt/anaconda3/envs/oaenv/lib/python3.9/socket.py", line 856, in create_connection
    raise err
  File "/opt/anaconda3/envs/oaenv/lib/python3.9/socket.py", line 844, in create_connection
    sock.connect(sa)
ConnectionRefusedError: [Errno 61] Connection refused
[2025-10-27T17:13:29.283-0400] {standard_task_runner.py:104} ERROR - Failed to execute job 4 for task check_environment (name 'json_files' is not defined; 61527)
[2025-10-27T17:13:29.289-0400] {local_task_job_runner.py:228} INFO - Task exited with return code 1
[2025-10-27T17:13:29.296-0400] {taskinstance.py:2776} INFO - 0 downstream tasks scheduled from follow-on schedule check
